File: resources/DSC_NH4Cl_refined_3.0K_min.csv
#EXPORTTYPE:                 ;DATA COMPARE
#FILE:                       ;26.07.23_NH4Cl_��_3kmin_30-500�.ngb-ds5
#FORMAT:                     ;NETZSCH5
#FTYPE:                      ;ANSI
#IDENTITY:                   ;NH4Cl_X4
#DECIMAL:                    ;COMMA
#SEPARATOR:                  ;SEMICOLON
#MTYPE:                      ;DSC
#INSTRUMENT:                 ;NETZSCH STA 449F5
#PROJECT:                    ;
#DATE/TIME:                  ;26.07.2023 13:34:14 (UTC+3)
#CORR. FILE:                 ;11.05.23_correction for composite-3kmin_30-500�.ngb-bs5
#TEMPCAL:                    ;3kmin-N2_washer+Al2O3+cover.ngb-ts5
#SENSITIVITY:                ;3kmin-N2_washer+Al2O3+cover.ngb-es5
#LABORATORY:                 ;
#OPERATOR:                   ;
#REMARK:                     ;
#SAMPLE:                     ;1
#SAMPLE MASS /mg:            ;21,8907
#MATERIAL:                   ;
#REFERENCE:                  ;
#REFERENCE MASS /mg:         ;0
#TYPE OF CRUCIBLE:           ;DSC/TG pan Al2O3
#SAMPLE CRUCIBLE MASS /mg:   ;0
#REFERENCE CRUCIBLE MASS /mg:;0
#DSC RANGE /�V:              ;5000
#TG RANGE /mg:               ;35000
#TAU-R:                      ;---
#CORR. CODE:                 ;020
#EXO:                        ;+1
#RANGE:                      ;30�C/3,0(K/min)/500�C
#SEGMENT:                    ;S1/1
#SEG. 1:                     ;30�C/3,0(K/min)/500�C

##Temp./�C;DSC/(mW/mg)
30,27800;-1,012354e-002
44.60172;-0.07034692
45.55664;-0.07121578
46.51155;-0.07342372
47.46647;-0.07462338
48.42138;-0.07661811
49.3763;-0.07787605
50.33121;-0.07872701
51.28613;-0.07983104
52.24104;-0.08151781
53.19596;-0.08163724
54.15087;-0.082682
55.10579;-0.08338114
56.0607;-0.08400882
57.01562;-0.08457309
57.97053;-0.08515197
58.92545;-0.08546313
59.88036;-0.08609402
60.83528;-0.08650924
61.79019;-0.08712228
62.74511;-0.08733156
63.70002;-0.08764697
64.65494;-0.08793283
65.60985;-0.08782696
66.56477;-0.0879138
67.51968;-0.08791362
68.4746;-0.08810001
69.42951;-0.08769652
70.38443;-0.08811031
71.33934;-0.08786636
72.29426;-0.08784182
73.24917;-0.08827833
74.20409;-0.08777821
75.159;-0.08742392
76.11392;-0.08744758
77.06883;-0.0874481
78.02375;-0.08709987
78.97866;-0.08691986
79.93358;-0.08657497
80.88849;-0.08622235
81.84341;-0.08618696
82.79832;-0.08587374
83.75324;-0.08543999
84.70815;-0.08503224
85.66307;-0.08482175
86.61798;-0.08442127
87.5729;-0.08363479
88.52781;-0.08345904
89.48273;-0.08296475
90.43764;-0.08215541
91.39256;-0.08179994
92.34747;-0.08114313
93.30239;-0.08051992
94.2573;-0.08008967
95.21222;-0.07923431
96.16713;-0.07890776
97.12205;-0.07815192
98.07696;-0.07775563
99.03188;-0.07675579
99.98679;-0.07695362
100.94171;-0.07616892
101.89662;-0.07570925
102.85154;-0.07480824
103.80645;-0.07421982
104.76137;-0.07396742
105.71628;-0.07329432
106.6712;-0.07244671
107.62611;-0.07187471
108.58103;-0.07109318
109.53594;-0.07091868
110.49086;-0.06991539
111.44577;-0.0694939
112.40069;-0.06909646
113.3556;-0.06811294
114.31052;-0.06782013
115.26543;-0.06731149
116.22035;-0.06671619
117.17526;-0.06613415
118.13018;-0.06561419
119.08509;-0.06491438
120.04001;-0.06442471
120.99492;-0.06350045
121.94984;-0.06294316
122.90475;-0.06237984
123.85967;-0.06178172
124.81458;-0.06081011
125.7695;-0.06044878
126.72441;-0.06027671
127.67933;-0.05892824
128.63424;-0.05839422
129.58916;-0.05811074
130.54407;-0.05752635
131.49899;-0.05697061
132.4539;-0.05584881
133.40882;-0.05545877
134.36373;-0.05489443
135.31865;-0.05385138
136.27356;-0.05365937
137.22848;-0.05284258
138.18339;-0.05238449
139.13831;-0.05203176
140.09322;-0.05153488
141.04814;-0.05064915
142.00305;-0.05015328
142.95797;-0.04976778
143.91288;-0.04895118
144.8678;-0.04848028
145.82271;-0.04794094
146.77763;-0.04742002
147.73254;-0.04675687
148.68746;-0.04623349
149.64237;-0.04519438
150.59729;-0.04504558
151.5522;-0.0445647
152.50712;-0.04375864
153.46203;-0.04380084
154.41695;-0.04273699
155.37186;-0.04261522
156.32678;-0.04174188
157.28169;-0.04176192
158.23661;-0.0415793
159.19152;-0.04100102
160.14644;-0.04059372
161.10135;-0.04014352
162.05627;-0.03962519
163.01118;-0.03905942
163.9661;-0.03884103
164.92101;-0.03830882
165.87593;-0.03803205
166.83084;-0.03739471
167.78576;-0.03757973
168.74067;-0.03717714
169.69559;-0.0373422
170.6505;-0.03656267
171.60542;-0.03670039
172.56033;-0.03678188
173.51525;-0.03651044
174.47016;-0.03625771
175.42508;-0.03653611
176.37999;-0.03687678
177.33491;-0.03648586
178.28982;-0.03666313
179.24474;-0.03672338
180.19965;-0.03691009
181.15457;-0.03717366
182.10948;-0.03742934
183.0644;-0.03747799
184.01931;-0.03778067
184.97423;-0.03952726
185.92914;-0.04657199
186.88406;-0.06021809
187.83897;-0.07960493
188.79389;-0.10662
189.7488;-0.13477
190.70372;-0.20103
191.65863;-0.27017
192.61355;-0.32549
193.56846;-0.37931
194.52338;-0.38112
195.47829;-0.32504
196.43321;-0.24807
197.38812;-0.17052
198.34304;-0.11422
199.29795;-0.07671783
200.25287;-0.05281378
201.20778;-0.03799951
202.1627;-0.02774801
203.11761;-0.02228528
204.07253;-0.01875632
205.02744;-0.01719226
205.98236;-0.01632274
206.93727;-0.01606807
207.89219;-0.01678266
208.8471;-0.0174338
209.80202;-0.01848989
210.75693;-0.0199122
211.71185;-0.02080521
212.66676;-0.02240395
213.62168;-0.02397942
214.57659;-0.02568419
215.53151;-0.02787894
216.48642;-0.02993709
217.44134;-0.03176363
218.39625;-0.03404666
219.35117;-0.03611474
220.30608;-0.03898561
221.261;-0.04176948
222.21591;-0.04491176
223.17083;-0.04761151
224.12574;-0.05070822
225.08066;-0.05441138
226.03557;-0.05746916
226.99049;-0.06114224
227.9454;-0.06481097
228.90032;-0.06918307
229.85523;-0.07307222
230.81015;-0.07691716
231.76506;-0.08191874
232.71998;-0.08641409
233.67489;-0.09174849
234.62981;-0.09685882
235.58472;-0.1026
236.53964;-0.10786
237.49455;-0.11326
238.44947;-0.11962
239.40438;-0.12486
240.3593;-0.13129
241.31421;-0.13771
242.26913;-0.14428
243.22404;-0.15164
244.17896;-0.15906
245.13387;-0.16715
246.08879;-0.17491
247.0437;-0.18296
247.99862;-0.19285
248.95353;-0.20132
249.90845;-0.20984
250.86336;-0.21938
251.81828;-0.22911
252.77319;-0.23866
253.72811;-0.24938
254.68302;-0.26062
255.63794;-0.27244
256.59285;-0.28379
257.54777;-0.29597
258.50268;-0.30792
259.4576;-0.32153
260.41251;-0.33442
261.36743;-0.34866
262.32234;-0.36275
263.27726;-0.37762
264.23217;-0.39295
265.18709;-0.40856
266.142;-0.42415
267.09692;-0.4417
268.05183;-0.45836
269.00675;-0.47658
269.96166;-0.4949
270.91658;-0.51317
271.87149;-0.53253
272.82641;-0.55212
273.78132;-0.57243
274.73624;-0.59346
275.69115;-0.61396
276.64607;-0.63651
277.60098;-0.65919
278.5559;-0.68192
279.51081;-0.7062
280.46573;-0.73008
281.42064;-0.75541
282.37556;-0.78131
283.33047;-0.8071
284.28539;-0.83567
285.2403;-0.86105
286.19522;-0.88978
287.15013;-0.9183
288.10505;-0.94731
289.05996;-0.97763
290.01488;-1.00719
290.96979;-1.03826
291.92471;-1.07037
292.87962;-1.10251
293.83454;-1.13653
294.78945;-1.16997
295.74437;-1.20335
296.69928;-1.23793
297.6542;-1.27101
298.60911;-1.30625
299.56403;-1.34448
300.51894;-1.3776
301.47386;-1.41169
302.42877;-1.44673
303.38369;-1.48614
304.3386;-1.52403
305.29352;-1.55738
306.24843;-1.59341
307.20335;-1.62793
308.15826;-1.65998
309.11318;-1.68399
310.06809;-1.70788
311.02301;-1.73825
311.97792;-1.77309
312.93284;-1.80326
313.88775;-1.83474
314.84267;-1.85196
315.79758;-1.86982
316.7525;-1.89159
317.70741;-1.91002
318.66233;-1.91249
319.61724;-1.89249
320.57216;-1.88318
321.52707;-1.87882
322.48199;-1.86076
323.4369;-1.82767
324.39182;-1.7639
325.34673;-1.68444
326.30165;-1.56089
327.25656;-1.38725
328.21148;-0.94066
329.16639;-0.5896
330.12131;-0.38517
331.07622;-0.26427
332.03114;-0.19116
332.98605;-0.14775
333.94097;-0.12291
334.89588;-0.1092
335.8508;-0.10167
336.80571;-0.09831521
337.76063;-0.09610638
338.71554;-0.0948293
339.67046;-0.09536621
340.62537;-0.09504075
341.58029;-0.09516312
342.5352;-0.09524599
343.49012;-0.09540096
344.44503;-0.0958845
345.39995;-0.09652604
346.35486;-0.0967538
347.30978;-0.09703069
348.26469;-0.09711382
349.21961;-0.09749329
350.17452;-0.09807943
351.12944;-0.09821768
352.08435;-0.0986119
353.03927;-0.09977398
353.99418;-0.09988176
354.9491;-0.10024
355.90401;-0.10067
356.85893;-0.10086
357.81384;-0.10138
358.76876;-0.10147
359.72367;-0.10225
360.67859;-0.10216
361.6335;-0.10407
362.58842;-0.10344
363.54333;-0.10316
364.49825;-0.10346
365.45316;-0.10401
366.40808;-0.10425
367.36299;-0.10532
368.31791;-0.10534
369.27282;-0.10623
370.22774;-0.10674
371.18265;-0.10724
372.13757;-0.1078
373.09248;-0.10818
374.0474;-0.10897
375.00231;-0.10985
375.95723;-0.11018
376.91214;-0.11046
377.86706;-0.11157
378.82197;-0.11219
379.77689;-0.11286
380.7318;-0.11299
381.68672;-0.11433
382.64163;-0.11453
383.59655;-0.11537
384.55146;-0.11673
385.50638;-0.11763
386.46129;-0.1185
387.41621;-0.11911
388.37112;-0.11998
389.32604;-0.12079
390.28095;-0.12149
391.23587;-0.12262
392.19078;-0.12287
393.1457;-0.12438
394.10061;-0.12518
395.05553;-0.12636
396.01044;-0.12711
396.96536;-0.12794
397.92027;-0.12884
398.87519;-0.12974
399.8301;-0.13086
400.78502;-0.13132
401.73993;-0.13267
402.69485;-0.13344
403.64976;-0.13451
404.60468;-0.13489
405.55959;-0.13633
406.51451;-0.13699
407.46942;-0.13798
408.42434;-0.13805
409.37925;-0.13831
410.33417;-0.13895
411.28908;-0.13979
412.244;-0.13997
413.19891;-0.14063
414.15383;-0.14056
415.10874;-0.141
416.06366;-0.14161
417.01857;-0.14185
417.97349;-0.14217
418.9284;-0.14268
419.88332;-0.14274
420.83823;-0.14305
421.79315;-0.14373
422.74806;-0.14401
423.70298;-0.14365
424.65789;-0.14367
425.61281;-0.1436
426.56772;-0.14349
427.52264;-0.14432
428.47755;-0.14477
429.43247;-0.14516
430.38738;-0.14513
431.3423;-0.14541
432.29721;-0.14547
433.25213;-0.14533
434.20704;-0.14571
435.16196;-0.14592
436.11687;-0.14567
437.07179;-0.14584
438.0267;-0.14612
438.98162;-0.14654
439.93653;-0.14694
440.89145;-0.14695
441.84636;-0.14735
442.80128;-0.14785
443.75619;-0.1486
444.71111;-0.14822
445.66602;-0.1492
446.62094;-0.15034
447.57585;-0.14997
448.53077;-0.15007
449.48568;-0.15052
450.4406;-0.15083
451.39551;-0.15091
452.35043;-0.15143
453.30534;-0.15173
454.26026;-0.1523
455.21517;-0.15368
456.17009;-0.15366
457.125;-0.1541
458.07992;-0.15426
459.03483;-0.15502
459.98975;-0.1547
460.94466;-0.15488
461.89958;-0.15552
462.85449;-0.15563
463.80941;-0.15633
464.76432;-0.15701
465.71924;-0.15687
466.67415;-0.15758
467.62907;-0.15766
468.58398;-0.15792
469.5389;-0.15873
470.49381;-0.15899
471.44873;-0.15968
472.40364;-0.15988
473.35856;-0.16025
474.31347;-0.1609
475.26839;-0.16179
476.2233;-0.16191
477.17822;-0.16235
478.13313;-0.16317
479.08805;-0.16274
480.04296;-0.16358
480.99788;-0.164
481.95279;-0.16436
482.90771;-0.16458
483.86262;-0.16552
484.81754;-0.16646
485.77245;-0.16723
486.72737;-0.16747
487.68228;-0.16821
488.6372;-0.16849
489.59211;-0.16922
490.54703;-0.1697
491.50194;-0.1696
492.45686;-0.17017
493.41177;-0.1708
494.36669;-0.17154
495.3216;-0.17135
496.27652;-0.17252
497.23143;-0.17265
498.18635;-0.1732