File: resources/DSC_NH4Cl_refined_5.0K_min.csv
#EXPORTTYPE:                 ;DATA COMPARE
#FILE:                       ;27.07.23_NH4Cl_��_5kmin_30-500�.ngb-ds5
#FORMAT:                     ;NETZSCH5
#FTYPE:                      ;ANSI
#IDENTITY:                   ;NH4CL_��
#DECIMAL:                    ;COMMA
#SEPARATOR:                  ;SEMICOLON
#MTYPE:                      ;DSC
#INSTRUMENT:                 ;NETZSCH STA 449F5
#PROJECT:                    ;
#DATE/TIME:                  ;27.07.2023 11:48:33 (UTC+3)
#CORR. FILE:                 ;10.05.23_correction for composite-5kmin_30-500�.ngb-bs5
#TEMPCAL:                    ;5kmin-N2_washer+Al2O3+cover.ngb-ts5
#SENSITIVITY:                ;5kmin-N2_washer+Al2O3+cover.ngb-es5
#LABORATORY:                 ;
#OPERATOR:                   ;
#REMARK:                     ;
#SAMPLE:                     ;1
#SAMPLE MASS /mg:            ;22,8865
#MATERIAL:                   ;
#REFERENCE:                  ;
#REFERENCE MASS /mg:         ;0
#TYPE OF CRUCIBLE:           ;DSC/TG pan Al2O3
#SAMPLE CRUCIBLE MASS /mg:   ;0
#REFERENCE CRUCIBLE MASS /mg:;0
#DSC RANGE /�V:              ;5000
#TG RANGE /mg:               ;35000
#TAU-R:                      ;---
#CORR. CODE:                 ;020
#EXO:                        ;+1
#RANGE:                      ;30�C/5,0(K/min)/500�C
#SEGMENT:                    ;S1/1
#SEG. 1:                     ;30�C/5,0(K/min)/500�C

##Temp./�C;DSC/(mW/mg)
30,27800;-8,425385e-003
44.60172;-0.09539767
45.55664;-0.09883508
46.51155;-0.10201
47.46647;-0.10462
48.42138;-0.10747
49.3763;-0.11022
50.33121;-0.11266
51.28613;-0.11458
52.24104;-0.11719
53.19596;-0.11892
54.15087;-0.12066
55.10579;-0.12231
56.0607;-0.12403
57.01562;-0.12578
57.97053;-0.12761
58.92545;-0.12901
59.88036;-0.13009
60.83528;-0.13145
61.79019;-0.13225
62.74511;-0.13309
63.70002;-0.13431
64.65494;-0.13502
65.60985;-0.13595
66.56477;-0.13668
67.51968;-0.13721
68.4746;-0.13777
69.42951;-0.13846
70.38443;-0.13899
71.33934;-0.13903
72.29426;-0.13938
73.24917;-0.13993
74.20409;-0.14031
75.159;-0.14041
76.11392;-0.14035
77.06883;-0.14018
78.02375;-0.14059
78.97866;-0.14055
79.93358;-0.14017
80.88849;-0.14078
81.84341;-0.14013
82.79832;-0.14012
83.75324;-0.13996
84.70815;-0.13974
85.66307;-0.13941
86.61798;-0.13909
87.5729;-0.13876
88.52781;-0.1386
89.48273;-0.13798
90.43764;-0.13751
91.39256;-0.13661
92.34747;-0.13668
93.30239;-0.13635
94.2573;-0.13532
95.21222;-0.13476
96.16713;-0.13409
97.12205;-0.13346
98.07696;-0.13287
99.03188;-0.13193
99.98679;-0.13128
100.94171;-0.13065
101.89662;-0.13001
102.85154;-0.12888
103.80645;-0.12848
104.76137;-0.12748
105.71628;-0.12662
106.6712;-0.12585
107.62611;-0.12519
108.58103;-0.12413
109.53594;-0.12302
110.49086;-0.12219
111.44577;-0.12108
112.40069;-0.12028
113.3556;-0.11909
114.31052;-0.11824
115.26543;-0.11771
116.22035;-0.116
117.17526;-0.11543
118.13018;-0.11388
119.08509;-0.11308
120.04001;-0.11141
120.99492;-0.11068
121.94984;-0.10916
122.90475;-0.10842
123.85967;-0.10747
124.81458;-0.10627
125.7695;-0.10483
126.72441;-0.10414
127.67933;-0.10356
128.63424;-0.10219
129.58916;-0.10088
130.54407;-0.0999714
131.49899;-0.0985972
132.4539;-0.0977945
133.40882;-0.09640348
134.36373;-0.09535598
135.31865;-0.09455986
136.27356;-0.09311634
137.22848;-0.09235343
138.18339;-0.09108764
139.13831;-0.0898607
140.09322;-0.0889382
141.04814;-0.08796816
142.00305;-0.08662653
142.95797;-0.08593867
143.91288;-0.08480321
144.8678;-0.08333521
145.82271;-0.08212218
146.77763;-0.08157866
147.73254;-0.08053237
148.68746;-0.07934895
149.64237;-0.078541
150.59729;-0.07751495
151.5522;-0.07628165
152.50712;-0.07549228
153.46203;-0.07440727
154.41695;-0.07363033
155.37186;-0.07229849
156.32678;-0.07152055
157.28169;-0.07030368
158.23661;-0.06963179
159.19152;-0.0686097
160.14644;-0.06787202
161.10135;-0.06704384
162.05627;-0.06618652
163.01118;-0.06509156
163.9661;-0.06421733
164.92101;-0.06350001
165.87593;-0.06262389
166.83084;-0.06184531
167.78576;-0.06080594
168.74067;-0.06032753
169.69559;-0.0594846
170.6505;-0.0586604
171.60542;-0.05774626
172.56033;-0.05705405
173.51525;-0.0568028
174.47016;-0.05577663
175.42508;-0.05519089
176.37999;-0.05490514
177.33491;-0.05382536
178.28982;-0.05323576
179.24474;-0.05271668
180.19965;-0.05246032
181.15457;-0.05172993
182.10948;-0.05129318
183.0644;-0.05075238
184.01931;-0.05038174
184.97423;-0.05085708
185.92914;-0.05689233
186.88406;-0.06537359
187.83897;-0.07980569
188.79389;-0.10239
189.7488;-0.12491
190.70372;-0.15965
191.65863;-0.21765
192.61355;-0.28516
193.56846;-0.35149
194.52338;-0.42214
195.47829;-0.45943
196.43321;-0.46554
197.38812;-0.44368
198.34304;-0.39498
199.29795;-0.32972
200.25287;-0.25945
201.20778;-0.19958
202.1627;-0.15314
203.11761;-0.11857
204.07253;-0.09251252
205.02744;-0.0728232
205.98236;-0.05768519
206.93727;-0.04622969
207.89219;-0.03759854
208.8471;-0.03214538
209.80202;-0.02759814
210.75693;-0.02449253
211.71185;-0.02252333
212.66676;-0.0217245
213.62168;-0.02084994
214.57659;-0.02069761
215.53151;-0.02141881
216.48642;-0.02196636
217.44134;-0.02266547
218.39625;-0.02359202
219.35117;-0.02506274
220.30608;-0.02664988
221.261;-0.02819594
222.21591;-0.03006383
223.17083;-0.03239195
224.12574;-0.03504542
225.08066;-0.03710546
226.03557;-0.03949759
226.99049;-0.04277999
227.9454;-0.04505028
228.90032;-0.04795204
229.85523;-0.05228114
230.81015;-0.05458504
231.76506;-0.05797061
232.71998;-0.06200105
233.67489;-0.0659492
234.62981;-0.07023066
235.58472;-0.07396721
236.53964;-0.07876818
237.49455;-0.08341348
238.44947;-0.08801044
239.40438;-0.09351575
240.3593;-0.09914066
241.31421;-0.10517
242.26913;-0.11112
243.22404;-0.11692
244.17896;-0.12248
245.13387;-0.12942
246.08879;-0.13664
247.0437;-0.14357
247.99862;-0.15079
248.95353;-0.1589
249.90845;-0.16629
250.86336;-0.17494
251.81828;-0.18355
252.77319;-0.19283
253.72811;-0.20233
254.68302;-0.21131
255.63794;-0.22199
256.59285;-0.23206
257.54777;-0.24273
258.50268;-0.25408
259.4576;-0.26493
260.41251;-0.27699
261.36743;-0.28904
262.32234;-0.30135
263.27726;-0.31474
264.23217;-0.32722
265.18709;-0.34171
266.142;-0.35591
267.09692;-0.37055
268.05183;-0.38571
269.00675;-0.40234
269.96166;-0.41828
270.91658;-0.43437
271.87149;-0.45191
272.82641;-0.46996
273.78132;-0.48862
274.73624;-0.50756
275.69115;-0.52619
276.64607;-0.54687
277.60098;-0.56734
278.5559;-0.58842
279.51081;-0.61037
280.46573;-0.63213
281.42064;-0.65578
282.37556;-0.67986
283.33047;-0.7038
284.28539;-0.72844
285.2403;-0.75439
286.19522;-0.78096
287.15013;-0.80799
288.10505;-0.83566
289.05996;-0.86392
290.01488;-0.89324
290.96979;-0.92406
291.92471;-0.95435
292.87962;-0.98562
293.83454;-1.01818
294.78945;-1.0507
295.74437;-1.08326
296.69928;-1.11788
297.6542;-1.15324
298.60911;-1.18851
299.56403;-1.22546
300.51894;-1.26269
301.47386;-1.30237
302.42877;-1.34266
303.38369;-1.38229
304.3386;-1.424
305.29352;-1.46655
306.24843;-1.50906
307.20335;-1.55126
308.15826;-1.59418
309.11318;-1.63557
310.06809;-1.67713
311.02301;-1.71841
311.97792;-1.76019
312.93284;-1.80377
313.88775;-1.84372
314.84267;-1.88697
315.79758;-1.93039
316.7525;-1.97771
317.70741;-2.02315
318.66233;-2.0677
319.61724;-2.11152
320.57216;-2.15523
321.52707;-2.2053
322.48199;-2.26308
323.4369;-2.32287
324.39182;-2.38541
325.34673;-2.44774
326.30165;-2.5119
327.25656;-2.57198
328.21148;-2.60872
329.16639;-2.6359
330.12131;-2.66476
331.07622;-2.69473
332.03114;-2.72056
332.98605;-2.75049
333.94097;-2.77433
334.89588;-2.79455
335.8508;-2.81394
336.80571;-2.83106
337.76063;-2.84652
338.71554;-2.86525
339.67046;-2.88105
340.62537;-2.86364
341.58029;-2.83396
342.5352;-2.80862
343.49012;-2.75948
344.44503;-2.67518
345.39995;-2.50976
346.35486;-2.2457
347.30978;-1.75243
348.26469;-1.22039
349.21961;-0.88288
350.17452;-0.62574
351.12944;-0.4478
352.08435;-0.31818
353.03927;-0.22277
353.99418;-0.15616
354.9491;-0.10703
355.90401;-0.07335804
356.85893;-0.05024387
357.81384;-0.03420835
358.76876;-0.02364341
359.72367;-0.01551245
360.67859;-0.01130867
361.6335;-0.007630215
362.58842;-0.006196505
363.54333;-0.004833688
364.49825;-0.003168983
365.45316;-0.00262713
366.40808;-0.002436667
367.36299;-0.002189427
368.31791;-0.001779215
369.27282;-0.001348397
370.22774;-0.001117251
371.18265;-0.0006940361
372.13757;-0.0008988566
373.09248;-0.0006290294
374.0474;-0.0004160372
375.00231;-0.0008280448
375.95723;-0.001000494
376.91214;-0.001090536
377.86706;-0.001207894
378.82197;-0.001082841
379.77689;-0.001400381
380.7318;-0.002070308
381.68672;-0.0007743246
382.64163;-0.001884033
383.59655;-0.002301575
384.55146;-0.002700985
385.50638;-0.003522536
386.46129;-0.003842661
387.41621;-0.004523304
388.37112;-0.005263378
389.32604;-0.005612927
390.28095;-0.006317708
391.23587;-0.00711496
392.19078;-0.007484822
393.1457;-0.008945535
394.10061;-0.009797336
395.05553;-0.0103156
396.01044;-0.01176972
396.96536;-0.0129099
397.92027;-0.01399392
398.87519;-0.01603003
399.8301;-0.0167303
400.78502;-0.01846545
401.73993;-0.02048917
402.69485;-0.02277532
403.64976;-0.02455788
404.60468;-0.02711703
405.55959;-0.02902145
406.51451;-0.03072129
407.46942;-0.03252596
408.42434;-0.03525146
409.37925;-0.0369089
410.33417;-0.03895268
411.28908;-0.04136648
412.244;-0.04316192
413.19891;-0.04441742
414.15383;-0.04633412
415.10874;-0.04774469
416.06366;-0.04931236
417.01857;-0.05070452
417.97349;-0.05180491
418.9284;-0.05270365
419.88332;-0.05310986
420.83823;-0.0542217
421.79315;-0.05478677
422.74806;-0.05467805
423.70298;-0.05518191
424.65789;-0.05524132
425.61281;-0.05524406
426.56772;-0.05413551
427.52264;-0.05414017
428.47755;-0.05373148
429.43247;-0.05341316
430.38738;-0.05347967
431.3423;-0.0530253
432.29721;-0.05222373
433.25213;-0.0525769
434.20704;-0.05258172
435.16196;-0.05262939
436.11687;-0.05232536
437.07179;-0.05260174
438.0267;-0.0530545
438.98162;-0.0531774
439.93653;-0.05384346
440.89145;-0.05403584
441.84636;-0.05454987
442.80128;-0.05534943
443.75619;-0.05656374
444.71111;-0.0566661
445.66602;-0.05770618
446.62094;-0.0582738
447.57585;-0.05922109
448.53077;-0.05991135
449.48568;-0.06024029
450.4406;-0.06113671
451.39551;-0.06215832
452.35043;-0.06320273
453.30534;-0.06370528
454.26026;-0.06489093
455.21517;-0.06603127
456.17009;-0.06686206
457.125;-0.068466
458.07992;-0.06967103
459.03483;-0.07061029
459.98975;-0.07186346
460.94466;-0.07239617
461.89958;-0.07397794
462.85449;-0.07496268
463.80941;-0.07621098
464.76432;-0.07675169
465.71924;-0.07815338
466.67415;-0.07946712
467.62907;-0.08020038
468.58398;-0.08101799
469.5389;-0.08199799
470.49381;-0.08310845
471.44873;-0.0842321
472.40364;-0.08455303
473.35856;-0.08579632
474.31347;-0.08735923
475.26839;-0.08834667
476.2233;-0.08958973
477.17822;-0.09015211
478.13313;-0.09122588
479.08805;-0.09166945
480.04296;-0.09254431
480.99788;-0.09318915
481.95279;-0.09425625
482.90771;-0.09465694
483.86262;-0.09615169
484.81754;-0.09735813
485.77245;-0.09766446
486.72737;-0.09812567
487.68228;-0.09916287
488.6372;-0.09926921
489.59211;-0.10056
490.54703;-0.10086
491.50194;-0.10194
492.45686;-0.10235
493.41177;-0.10239
494.36669;-0.10284
495.3216;-0.10359
496.27652;-0.10365
497.23143;-0.10461
498.18635;-0.10463